Workbook
Name a: #REF!
Name a: #REF!
Name B: #REF!
Name B: #REF!
Name Compactação: #REF!
Name Compactação: #REF!
Name d: #REF!
Name d: #REF!
Name da: #REF!
Name da: #REF!
Name dd: #REF!
Name dd: #REF!
Name f: #REF!
Name f: #REF!
Name H: #REF!
Name H: #REF!
Name k: #REF!
Name k: #REF!
Name kk: #REF!
Name kk: #REF!
Name Liquidez: #REF!
Name Liquidez: #REF!
Name non: #REF!
Name non: #REF!
Name o: #REF!
Name o: #REF!
Name oi: #REF!
Name oi: #REF!
Name ou: #REF!
Name ou: #REF!
Name oui: #REF!
Name oui: #REF!
Name p: #REF!
Name p: #REF!
Name Plasticidade: #REF!
Name Plasticidade: #REF!
Name Platicidade: #REF!
Name Platicidade: #REF!
Name q: #REF!
Name q: #REF!
Name sa: #REF!
Name sa: #REF!
Name sandro: #REF!
Name sandro: #REF!
Name sq: #REF!
Name sq: #REF!
Name ss: #REF!
Name ss: #REF!
Name w: #REF!
Name w: #REF!
Name xa: #REF!
Name xa: #REF!

Sheet PAGE RECAP  P1
C1: Bureau de Contrôle du Bâtiment et des Travaux Publics
M2: Technicien : NGOMA-NZAOU Drège
A3: PROVENANCE | E3: Corniche Brazzaville - Tronçon Fulbert YOULOU Pont du Djoué - Puit 5 - 1 ère couche
A4: DATE DE PRELEVEMENT | F4: 43808 | J4: DATE DES ESSAIS | N4: 43809 | S4: - | T4: 43823
A6: Nature de l'échantillon | F6: Sable limoneux gris
A7: Observations | F7: Profondeur 0,10 m - 0,60 m
A10: ESSAIS D'IDENTIFICATION | N10: Classification USHRB
A11: W.L. | G11: Teneur en eau naturelle % | K11: ='Teneur en eau 2 P1 '!F41 -> 10.049833
A12: W.P. | D12: - | G12: Poids spécifique ys (g/cm3) | K12: =PS!G42 -> 2.5631116 | N12: E.S(%) | R12: 24 | AB12: 300
A13: I.P. | D13: - | G13: % 80 microns | K13: =E34 -> 17.633333 | N13: f x IP | R13: -
B15: Tamis | C15: Poids refus | D15: Pourcentage cumulé | E15: Tamisats
B16: <mm | AC16: 63
B17: 40 | C17: ='Granulo P1'!L23 -> 0 | D17: =(C17*100)/'Granulo P1'!C17:C18 -> 0 | E17: =100-D17 -> 100 | AC17: 50
B18: 31.5 | C18: ='Granulo P1'!L24 -> 0 | D18: =(C18*100)/'Granulo P1'!C17 -> 0 | E18: =100-D18 -> 100 | AC18: 40 | AD18: =E17 -> 100
B19: 20 | C19: ='Granulo P1'!L26 -> 14.5 | D19: =(C19*100)/'Granulo P1'!C17 -> 4.8333333 | E19: =100-D19 -> 95.166667 | AC19: 31.5 | AD19: =E18 -> 100
B20: 10 | C20: ='Granulo P1'!L29 -> 34.7 | D20: =(C20*100)/'Granulo P1'!C17 -> 11.566667 | E20: =100-D20 -> 88.433333 | AC20: 20 | AD20: =E19 -> 95.166667
B21: 6.3 | AC21: 10 | AD21: =E20 -> 88.433333
B22: 5 | C22: ='Granulo P1'!L32 -> 44.5 | D22: =(C22*100)/'Granulo P1'!C17 -> 14.833333 | E22: =100-D22 -> 85.166667 | AC22: 5 | AD22: =E22 -> 85.166667
B23: 4 | AC23: 2 | AD23: =E25 -> 82.2
B24: 2.5 | AC24: 1 | AD24: =E27 -> 79.366667
B25: 2 | C25: ='Granulo P1'!L36 -> 53.4 | D25: =(C25*100)/'Granulo P1'!C17 -> 17.8 | E25: =100-D25 -> 82.2 | AC25: 0.4 | AD25: =E29 -> 62.666667
B26: 1.25 | AC26: 0.2 | AD26: =E31 -> 37.333333
B27: 1 | C27: ='Granulo P1'!L39 -> 61.9 | D27: =(C27*100)/'Granulo P1'!C17 -> 20.633333 | E27: =100-D27 -> 79.366667 | AC27: 0.1 | AD27: =E33 -> 20.2
B28: 0.63 | AC28: 0.08 | AD28: =E34 -> 17.633333
B29: 0.4 | C29: ='Granulo P1'!L43 -> 112 | D29: =(C29*100)/'Granulo P1'!C17 -> 37.333333 | E29: =100-D29 -> 62.666667
B30: 0.315
B31: 0.2 | C31: ='Granulo P1'!L46 -> 188 | D31: =(C31*100)/'Granulo P1'!C17 -> 62.666667 | E31: =100-D31 -> 37.333333
B32: 0.16
B33: 0.1 | C33: ='Granulo P1'!L49 -> 239.4 | D33: =(C33*100)/'Granulo P1'!C17 -> 79.8 | E33: =100-D33 -> 20.2
B34: 0.08 | C34: ='Granulo P1'!L50 -> 247.1 | D34: =(C34*100)/'Granulo P1'!C17 -> 82.366667 | E34: =100-D34 -> 17.633333
A36: ESSAI PROCTOR MODIFIE | L36: Essai C.B.R. | O36: gd | Q36: W% de | S36: W% après 4j | U36: GONFLEMENT
D37: Essai Proctor | G37: Correction | L37: Nbre de coups | O37: (kN/m3) | Q37: MOULAGE | S37: IMBIBITION | U37: %
A38: yd OPM (T/m3) | D38: =Y54 -> 2.103 | L38: 56 | O38: =M44 -> 2.1029887 | S38: =' CBR Poinc'!L33 -> 8.9539137 | U38: 0
A39: W OPM (%) | D39: =X54 -> 7.2 | L39: 25 | O39: =N44 -> 1.9977936 | S39: =' CBR Poinc'!O33 -> 9.2643052 | U39: 0
A40: % > 20 mm | L40: 10 | O40: =O44 -> 1.8934572 | S40: =' CBR Poinc'!R33 -> 9.3343535 | U40: 0
A42: Pts | B42: 1 | C42: 2 | D42: 3 | E42: 4 | F42: 5 | G42: 6 | H42: OPM | L42: Pts | M42: 56 cps | N42: 25 cps | O42: 10 cps | R42: OPM | S42: 1 | T42: 0.98 | U42: 0.95 | V42: 0.9
A43: w% | B43: ='Proctor C01 (2)'!$B$41:$C$41 -> 4.0757194 | C43: ='Proctor C01 (2)'!$D$41 -> 6.1550749 | D43: ='Proctor C01 (2)'!$F$41 -> 8.139868 | E43: ='Proctor C01 (2)'!$H$41 -> 10.146563 | F43: ='Proctor C01 (2)'!$J$41 -> 12.042723 | H43: ='Proctor C01 (2)'!B44 -> 7.2 | L43: CBR | M43: ='CBR Crb (2)'!$C$26 -> 30.386406 | N43: ='CBR Crb (2)'!$D$26 -> 21.348742 | O43: ='CBR Crb (2)'!$E$26 -> 12.019541 | R43: CBR | U43: =X47 -> 21.4
A44: gd | B44: ='Proctor C01 (2)'!$B$33:$C$33 -> 1.9713939 | C44: ='Proctor C01 (2)'!$D$33 -> 2.0889525 | D44: ='Proctor C01 (2)'!$F$33 -> 2.0916242 | E44: ='Proctor C01 (2)'!$H$33 -> 2.0055835 | F44: ='Proctor C01 (2)'!$J$33 -> 1.9245186 | H44: ='Proctor C01 (2)'!B43 -> 2.103 | L44: gd | M44: ='CBR Crb (2)'!$C$27 -> 2.1029887 | N44: ='CBR Crb (2)'!$D$27 -> 1.9977936 | O44: ='CBR Crb (2)'!$E$27 -> 1.8934572 | R44: gd | S44: =D38 -> 2.103 | T44: =0.98*D38 -> 2.06094 | U44: =Y47 -> 1.99785 | V44: =0.9*D38 -> 1.8927
X46: CBR à 95% | AA46: 1.5087425 | AC46: 1.7608815 | AE46: 1.8072857 | AG46: 1.7050329 | AI46: 1.6033512
X47: ='CBR Crb (2)'!T28 -> 21.4 | Y47: ='CBR Crb (2)'!U28 -> 1.99785
...

Sheet Teneur en eau 2 P1 
B1: PROCES-VERBAL D'ESSAIS
A2: Direction du Laboratoire | B2: Détermination de la teneur en eau pondérale des sols | N2: Direction du Laboratoire
B3: - Méthode par étuvage-
B4: NF P 94-050/ Septembre 1995
A6: Date de l'essai: | B6: 43809 | H6: Référence échantillon: | L6: Puit 5 - Sable Gréseux
A9: Masse minimale de la prise d'essai:
A11: dm (µm) | B11: 400 | E11: 500 | H11: 630 | K11: 800 | N11: 1000
A12: Masse (g) | B12: 20 | E12: 50 | H12: 100 | K12: 150 | N12: 200
A14: dm (mm) | B14: 5 | C14: 6.3 | D14: 8 | E14: 10 | F14: 12.5 | G14: 16 | H14: 20 | I14: 25 | J14: 31.5 | K14: 40 | L14: 50 | M14: 63 | N14: 80 | O14: dm >80mm
A15: Masse (g) | B15: 0.3 | C15: 0.4 | D15: 0.5 | E15: 0.8 | F15: 1.2 | G15: 2 | H15: 3 | I15: 5 | J15: 8 | K15: 12 | L15: 20 | M15: 30 | N15: 50 | O15: m=6.106 dm 3,66
A18: Mesure de la teneur en eau
A20: ETUVE:
A21: Etuvage à :
E23: 50°C | M23: 105 °C
A25: TARE:
A27: Tare n°:……… | B27: T'/B9 | H27: Masse de la tare:m1=……….. | M27: 32.8 | O27: 36.2 | P27: ....g.
A29: Masse avant étuvage : Prise de l'essai+tare: | H29: m2 = m+m1 =...……… | M29: 256.5 | O29: 266.9 | P29: ...g.
O30: 193.6
A31: Masse après étuvage, prise d'essai + tare : | K31: M3=…….….. | M31: 236.2 | O31: 245.7 | P31: …...g.
A33: TENEUR EN EAU:
A35: mw: masse de l'eau évaporée lors de l'étuvage
A36: md : masse des grains solides
S37: =(M29-M31)/(M31-M27)*100 -> 9.9803343 | T37: =(O29-O31)/(O31-O27)*100 -> 10.119332
A41: W= | F41: =AVERAGE(S37:T37) -> 10.049833 | I41: .…...…%
A46: Responsable de l'essai: | I46: Exécuté par
A50: BEANGE Grace

Sheet Granulo P1
B1: PROCES-VERBAL D'ESSAIS | L1: Référence: | N1: :FEE/310/18
A2: Direction du Laboratoire | B2: Sols : reconnaissance et essais Analyse granulométrique : Méthode par tamisage à sec après lavage | L2: Indice | N2: :0 1
L3: Date appl | N3: :30-10-2018
B4: NF P 94-056/ Mars 1996 | L4: Page | N4: : 1/1
A6: Date de l'essai: | B6: 43813 | F6: Référence échantillon: | K6: Sable Gréseux - P 5 -1ère couche
A9: Masse minimale de la prise d'essai:
A12: dm (mm) | B12: 5 | C12: 6.3 | D12: 8 | E12: 10 | F12: 12.5 | G12: 16 | H12: 20 | I12: 25 | J12: 31.5 | K12: 40 | L12: 63 | M12: 80 | N12: dm >80mm
A13: Masse (g) | B13: 0.3 | C13: 0.4 | D13: 0.5 | E13: 0.8 | F13: 1.2 | G13: 2 | H13: 3 | I13: 5 | J13: 8 | K13: 12 | L13: 30 | M13: 50 | N13: m=6.106 dm 3,66
A15: Matériau | B15: Masse de la prisse d'essai | E15: Tamis | H15: Masse refus mesuré (g) | L15: Masse refus R cumulé (g) | N15: Pourcentage massique
A17: dm= mm | B17: m= | C17: 300 | D17: g | E17: mm | F17: µm | H17: r i | J17: R | N17: Refus cumulé r | O17: Tamisât cumulé p
A19: Partage au tamis dc : | D19: ..mm | E19: 100
E20: 80
A21: Masse sèche du refus au tamis dc: | E21: 63
A22: RC=………………… | D22: …….g | E22: 50
A23: Masse passant au tamis dc: | E23: 40 | L23: =J23 -> 0 | N23: =L23/C17*100 -> 0 | O23: =100-N23 -> 100
A24: mh= ………………. | D24: …….g | E24: 31.5 | J24: 0 | L24: =L23+J24 -> 0 | N24: =L24/C17*100 -> 0 | O24: =100-N24 -> 100
A25: Part (1) sur tamisat au tamis dc | B25: Masse humide: | E25: 25
B26: Mh1 =.. | D26: ……..g | E26: 20 | J26: 14.5 | L26: =L24+J26 -> 14.5 | N26: =L26/C17*100 -> 4.8333333 | O26: =100-N26 -> 95.166667
B27: Masse sèche: | E27: 16
B28: Ms1 | D28: ..…..g | E28: 12.5
A29: Part (2) sur tamisat au tamis dc | B29: Masse humide: | E29: 10 | J29: 20.2 | L29: =J29+L26 -> 34.7 | N29: =L29/C17*100 -> 11.566667 | O29: =100-N29 -> 88.433333
B30: Mh1 =.. | D30: ……..g | E30: 8
B31: Masse sèche: | E31: 6.3
B32: Ms1… | D32: ……..g | E32: 5 | J32: 9.8 | L32: =J32+L29 -> 44.5 | N32: =L32/C17*100 -> 14.833333 | O32: =100-N32 -> 85.166667
A33: Masse sèche totale: | E33: 4
A34: ms=Rc+mh.ms1/mh1=…… | D34: ……..g | E34: 3.15
A35: Coefficient multiplicateur sur le refus au tamis de 80µm: | E35: 2.5
E36: 2 | J36: 8.9 | L36: =J36+L32 -> 53.4 | N36: =L36/C17*100 -> 17.8 | O36: =100-N36 -> 82.2
A37: b=mh/mh2:……..……….. | D37: ………. | E37: 1.6
A38: Refus cumulé R = RC + br1 | E38: 1.25
A39: Masse (80µm,dc):ms4= Prélèvement 2 | D39: ……..g | E39: 1 | J39: 8.5 | L39: =J39+L36 -> 61.9 | N39: =L39/C17*100 -> 20.633333 | O39: =100-N39 -> 79.366667
E40: 0.8 | F40: 800
A41: Masse passant à 80µm de lafraction (80µm,dc ): | E41: 0.63 | F41: 630
E42: 0.5 | F42: 500
A43: Sur part(2)ms3 =……………. | D43: ……g | E43: 0.4 | F43: 400 | J43: 50.1 | L43: =J43+L39 -> 112 | N43: =L43/C17*100 -> 37.333333 | O43: =100-N43 -> 62.666667
E44: 0.315 | F44: 315
A45: Pourcentage | C45: Refus: | E45: 0.25 | F45: 250
C46: R = 100 R/ms | E46: 0.2 | F46: 200 | J46: 76 | L46: =J46+L43 -> 188 | N46: =L46/C17*100 -> 62.666667 | O46: =100-N46 -> 37.333333
C47: De tamisat: | E47: 0.16 | F47: 160
C48: 100(1-R/ms) | E48: 0.125 | F48: 125
...

Sheet Courbe P1 (2)
B1: PROCES-VERBAL D'ESSAIS | L1: Référence: | N1: :FEE/310/18
A2: Direction du Laboratoire | B2: Sols : reconnaissance et essais Analyse granulométrique : Méthode par tamisage à sec après lavage | L2: Indice | N2: :0 1
L3: Date appl | N3: :30-10-2018
B4: Effectuée conformement à la norme NF P 94-056/ Mars 1996 | L4: Page | N4: : 1/1
A6: Date de l'essai: | B6: ='Granulo P1'!B6:E6 -> 43813 | G6: Référence échantillon: | L6: ='Granulo P1'!K6 -> Sable Gréseux - P 5 -1ère couche
A9: Masse minimale de la prise d'essai:
A12: dm (mm) | B12: 5 | C12: 6.3 | D12: 8 | E12: 10 | F12: 12.5 | G12: 16 | H12: 20 | I12: 25 | J12: 31.5 | K12: 40 | L12: 63 | M12: 80 | N12: dm >80mm
A13: Masse (g) | B13: 0.3 | C13: 0.4 | D13: 0.5 | E13: 0.8 | F13: 1.2 | G13: 2 | H13: 3 | I13: 5 | J13: 8 | K13: 12 | L13: 30 | M13: 50 | N13: m=6.106 dm 3,66
T19: 40 | U19: ='Granulo P1'!O23 -> 100
T20: 31.5 | U20: ='Granulo P1'!O24 -> 100
T21: 20 | U21: ='Granulo P1'!O26 -> 95.166667
T22: 10 | U22: ='Granulo P1'!O29 -> 88.433333
T23: 5 | U23: ='Granulo P1'!O32 -> 85.166667
T24: 2 | U24: ='Granulo P1'!O36 -> 82.2
T25: 1 | U25: ='Granulo P1'!O39 -> 79.366667 | W25: 99.9
T26: 0.4 | U26: ='Granulo P1'!O43 -> 62.666667 | W26: 83.633333
T27: 0.2 | U27: ='Granulo P1'!O46 -> 37.333333 | W27: 41.6
T28: 0.1 | U28: ='Granulo P1'!O49 -> 20.2 | W28: 11.966667
T29: 0.08 | U29: ='Granulo P1'!O50 -> 17.633333 | W29: 8.0333333

Sheet PS
A11: POIDS SPECIFIQUE
G13: Date : 17/10/2019
E15: Expérimentateur :BEANGE Grace
A16: Nature :Sable Gréseux ,Profondeur 0,10 m - 0,60 m, Puit 1 - 1ème couche
A17: N° PYCNOMETRE | G17: 7 | H17: 5
A18: Poids Pycnomètre vide = PO | G18: 253.4 | H18: 283.1
A20: Poids Pycnomètre + Matériaux Sec = P2 | G20: 503.1 | H20: 533.2
A22: Poids Pycnomètre + Matériaux +Eau =P3 | G22: 952.5 | H22: 967.5
A24: Poids Pycnomètre + Eau =P1 | G24: 799.9 | H24: 815.3
A28: Volume Pycnomètre = P1-P0 = P4 | G28: =G24-G18 -> 546.5 | H28: =H24-H18 -> 532.2
A30: Volume Matériaux Net Sec = P2-P0 = P5 | G30: =G20-G18 -> 249.7 | H30: =H20-H18 -> 250.1
A32: Volume d'Eau Restant = P3-P2= P6 | G32: =G22-G20 -> 449.4 | H32: =H22-H20 -> 434.3
A34: Volume Matériaux = P4-P6= VM* | G34: =G28-G32 -> 97.1 | H34: =H28-H32 -> 97.9
A38: Poids Spécifique | G38: =G30/G34 -> 2.5715757 | H38: =H30/H34 -> 2.5546476
A42: Moyenne | G42: =AVERAGE(G38,H38,I38) -> 2.5631116
A44: Observation:
A46: Opérateur: | E46: Chargé d'affaire:

Sheet Proctor C01 (2)
B1: Bureau de Contrôle du Bâtiment et des Travaux Publics(B.C.B.T.P) | J1: Enregistrement:
B2: Fiche d'Essai | J2: Page:1/1
J3: Mise à jour:
A5: N° d'affaire | B5: DETERMINATION DES REFERENCES DE COMPACTAGE
B6: D'UN MATERIAU
B7: Essai Proctor normal-Essai Proctor modifié
A10: NORME: NF P94-093 Octobre 1999
A11: Localisation du chantier: Corniche Pont du Djoué
A12: Nom du client: | E12: Nature de materiaux: Sable Gréseux
A13: N° de reception: | E13: Utilisation:
A14: Date de reception: | E14: Mode de prélevement: Manuel
A15: Provenance: Puit 5 1ère couche | E15: Prélevement effectué: BCBTP
A17: PROCTOR | C17: NORMAL | H17: MODIFIE | K17: X
C18: Moule Proctor | E18: Moule CBR | H18: Moule Proctor | J18: Moule CBR
A19: Masse de la dame | C19: 2490g | H19: 4535g
A20: Diamètre du mouton | C20: 51mm | H20: 51mm
A21: Hauteur de chute | C21: 305mm | H21: 457mm
A22: Nombre de couches | C22: 3 | H22: 5
A23: Nombre de coups par couche | C23: 25 | E23: 56 | H23: 25 | J23: 56
A24: Diamètre maxi(mm) | B24: 1 | E24: Pourcentage de refus au tamis 20mm | I24: 0
A25: DENSITE
A26: N° Moule | B26: B | D26: B | F26: B | H26: B | J26: B
A27: Eau de moulage(%) | B27: 4 | D27: 6 | F27: 8 | H27: 10 | J27: 12
A28: Poids du moule | B28: 4032 | D28: 4032 | F28: 4032 | H28: 4032 | J28: 4032
A29: Poids moule+ sol humide | B29: 5975 | D29: 6132 | F29: 6174 | H29: 6124 | J29: 6074
A30: Poids net humide | B30: =B29-B28 -> 1943 | D30: =D29-D28 -> 2100 | F30: =F29-F28 -> 2142 | H30: =H29-H28 -> 2092 | J30: =J29-J28 -> 2042
A31: Volume du moule | B31: 947 | D31: 947 | F31: 947 | H31: 947 | J31: 947
A32: Densité humide | B32: =B30*1/B31 -> 2.0517423 | D32: =D30*1/D31 -> 2.217529 | F32: =F30*1/F31 -> 2.2618796 | H32: =H30*1/H31 -> 2.2090813 | J32: =J30*1/J31 -> 2.156283
A33: Densité sèche | B33: =(B32)*100/(100+B41) -> 1.9713939 | D33: =(D32)*100/(100+D41) -> 2.0889525 | F33: =(F32)*100/(100+F41) -> 2.0916242 | H33: =(H32)*100/(100+H41) -> 2.0055835 | J33: =(J32)*100/(100+J41) -> 1.9245186
A34: TENEUR EN EAU
A35: N° Tare | B35: C | C35: 10 | D35: 23 | E35: 40 | F35: 43 | G35: DB1 | H35: 33 | I35: DL | J35: 88 | K35: 4
A36: Poids de la tare | B36: 15.7 | C36: 34.7 | D36: 34.8 | E36: 33.2 | F36: 35.5 | G36: 34.7 | H36: 23.2 | I36: 15.3 | J36: 33.4 | K36: 24.2
A37: Poids tare+ sol humide | B37: 171.4 | C37: 254.4 | D37: 268.9 | E37: 256.2 | F37: 213.4 | G37: 231.6 | H37: 167.8 | I37: 143.2 | J37: 264.8 | K37: 270.1
A38: Poids tare+ sol sec | B38: 165.3 | C38: 245.8 | D38: 255.4 | E38: 243.2 | F38: 199.9 | G38: 216.9 | H38: 154.5 | I38: 131.4 | J38: 239.9 | K38: 243.7
A39: Poids sec | B39: =B38-B36 -> 149.6 | C39: =C38-C36 -> 211.1 | D39: =D38-D36 -> 220.6 | E39: =E38-E36 -> 210 | F39: =F38-F36 -> 164.4 | G39: =G38-G36 -> 182.2 | H39: =H38-H36 -> 131.3 | I39: =I38-I36 -> 116.1 | ... K39: =K38-K36 -> 219.5
A40: Teneur en eau | B40: =((B37)-(B38))*100/B39 -> 4.0775401 | C40: =((C37)-(C38))*100/C39 -> 4.0738986 | D40: =((D37)-(D38))*100/D39 -> 6.1196736 | E40: =((E37)-(E38))*100/E39 -> 6.1904762 | F40: =((F37)-(F38))*100/F39 -> 8.2116788 | G40: =((G37)-(G38))*100/G39 -> 8.0680571 | H40: =((H37)-(H38))*100/H39 -> 10.129474 | I40: =((I37)-(I38))*100/I39 -> 10.163652 | ... K40: =((K37)-(K38))*100/K39 -> 12.027335
A41: Teneur en eau moyenne | B41: =AVERAGE(B40:C40) -> 4.0757194 | D41: =AVERAGE(D40:E40) -> 6.1550749 | F41: =AVERAGE(F40:G40) -> 8.139868 | H41: =AVERAGE(H40:I40) -> 10.146563 | J41: =AVERAGE(J40:K40) -> 12.042723
A43: Densité OPM(t/m³) | B43: =O52 -> 2.103 | F43: Paramètres après correction | I43: =B43 -> 2.103 | K43: t/m³
A44: Teneur en eau OPM(%) | B44: =N52 -> 7.2 | I44: =B44 -> 7.2 | K44: %
N51: w | O51: den
...

Sheet  CBR Poinc
G1: ESSAI CBR | N1: Projet
N2: Etude
G3: Norme NF P 94-078
A4: Nom du projet : | D4: Corniche Pont du Djoué | J4: Date prélèvement :
A5: Site : | J5: Lieu de prélèvement : | N5: Puit 5 - 1ère couche
A6: Client : | J6: N° Dossier :
A7: Date de l'essai : | D7: Du 20/12/2019 au 24/12/2019 | J7: Profondeur (m) :
J8: Nature de l'échantillon: | N8: Sable Gréseux
A9: Essai | B9: I. CBR Immédiat | H9: Moule | I9: CBR | K9: x | M9: Matériau | O9: Non traité | Q9: x
B10: I.CBR Immersion | E10: x | I10: Nbre disques | K10: 2 | O10: Traité
B11: IPI | O11: Liant | P11: Neant
B12: Durée immersion | E12: 96h | H12: ρdOP (g/cm3) | J12: ='Proctor C01 (2)'!B43 -> 2.103 | K12: t/m3 | M12: Denité sèche | P12: =J12 -> 2.103 | Q12: g/cm3
H13: wop | J13: ='Proctor C01 (2)'!B44 -> 7.2 | K13: % | M13: Mesurée | P13: Estimée | Q13: x
A14: Essai après imbibition
A15: Teneur en eau de compactage | K15: Poinconnement
A16: Coups | C16: 56 | E16: 25 | G16: 10 | J16: 56 coups | M16: 25 coups | P16: 10 coups
A17: Essai N° | C17: 1 | D17: 2 | E17: 1 | F17: 2 | G17: 1 | H17: 2 | J17: Enf,(mm) | K17: Lecture | L17: Effort (kN) | M17: Enf,(mm) | N17: Lecture | O17: Effort (kN) | P17: Enf,(mm) | Q17: Lecture | R17: Effort (kN)
A18: N° de la tare | C18: 11' | D18: 36A | E18: B100 | F18: B23 | G18: DB6 | H18: B44 | J18: 0 | K18: 0 | L18: 0 | M18: 0 | N18: 0 | O18: 0 | P18: 0 | Q18: 0 | R18: 0
A19: tare | C19: 24.4 | D19: 37.2 | E19: 35.3 | F19: 35.4 | G19: 23.4 | H19: 34.7 | J19: 0.5 | K19: 0.22 | L19: =((K19*9.8977)-0.3056)*10 -> 18.71894 | M19: 0.5 | N19: 0.12 | O19: =((N19*9.8977)-0.3056)*10 -> 8.82124 | P19: 0.5 | Q19: 0.07 | R19: =((Q19*9.8977)-0.3056)*10 -> 3.87239
A20: Mh+tare | C20: 199.9 | D20: 213.2 | E20: 246.8 | F20: 242 | G20: 140 | H20: 197.8 | J20: 1 | K20: 1.6 | L20: =((K20*9.8977)-0.3056)*10 -> 155.3072 | M20: 1 | N20: 0.87 | O20: =((N20*9.8977)-0.3056)*10 -> 83.05399 | P20: 1 | Q20: 0.43 | R20: =((Q20*9.8977)-0.3056)*10 -> 39.50411
A21: Ms + tare | C21: 188.1 | D21: 201.4 | E21: 232.6 | F21: 228.1 | G21: 132.2 | H21: 186.9 | J21: 1.5 | K21: 2.75 | L21: =((K21*9.8977)-0.3056)*10 -> 269.13075 | M21: 1.5 | N21: 1.89 | O21: =((N21*9.8977)-0.3056)*10 -> 184.01053 | P21: 1.5 | Q21: 0.93 | R21: =((Q21*9.8977)-0.3056)*10 -> 88.99261
A22: w (%) | C22: =IF(C21<>0, (C20-C21)/(C21-C19)*100, "") -> 7.2083079 | D22: =(D20-D21)/(D21-D19)*100 -> 7.1863581 | E22: =IF(E21<>0, (E20-E21)/(E21-E19)*100, "") -> 7.1971617 | F22: =(F20-F21)/(F21-F19)*100 -> 7.2132849 | G22: =(G20-G21)/(G21-G19)*100 -> 7.1691176 | H22: =(H20-H21)/(H21-H19)*100 -> 7.1616294 | J22: 2 | K22: 3.55 | L22: =((K22*9.8977)-0.3056)*10 -> 348.31235 | M22: 2 | N22: 2.53 | O22: =((N22*9.8977)-0.3056)*10 -> 247.35581 | P22: 2 | Q22: 1.27 | R22: =((Q22*9.8977)-0.3056)*10 -> 122.64479
A23: w Moyenne | C23: =AVERAGE(C22:D22) -> 7.197333 | E23: =AVERAGE(E22:F22) -> 7.2052233 | G23: =AVERAGE(G22:H22) -> 7.1653735 | J23: 2.5 | K23: 4.2 | L23: =((K23*9.8977)-0.3056)*10 -> 412.6474 | M23: 2.5 | N23: 2.96 | O23: =((N23*9.8977)-0.3056)*10 -> 289.91592 | P23: 2.5 | Q23: 1.68 | R23: =((Q23*9.8977)-0.3056)*10 -> 163.22536
A24: % wop | C24: =C23/J13*100 -> 99.962958 | E24: =E23/J13*100 -> 100.07255 | G24: =G23/J13*100 -> 99.519077 | J24: 5 | K24: 4.94 | L24: =((K24*9.8977)-0.3056)*10 -> 485.89038 | M24: 5 | N24: 3.69 | O24: =((N24*9.8977)-0.3056)*10 -> 362.16913 | P24: 5 | Q24: 2.03 | R24: =((Q24*9.8977)-0.3056)*10 -> 197.86731
A25: Densité sèche de compactage | J25: 6 | K25: 5.2 | L25: =((K25*9.8977)-0.3056)*10 -> 511.6244 | M25: 6 | N25: 3.75 | O25: =((N25*9.8977)-0.3056)*10 -> 368.10775 | P25: 6 | Q25: 2.27 | R25: =((Q25*9.8977)-0.3056)*10 -> 221.62179
A26: N° du moule | D26: ME | F26: NK' | H26: QBC | J26: 10 | K26: 5.93 | L26: =((K26*9.8977)-0.3056)*10 -> 583.87761 | M26: 10 | N26: 3.92 | O26: =((N26*9.8977)-0.3056)*10 -> 384.93384 | P26: 10 | Q26: 2.65 | R26: =((Q26*9.8977)-0.3056)*10 -> 259.23305
A27: Moule (g) | D27: 3770 | F27: 3742 | H27: 3854
A28: Moule + sol (g) | D28: 8955 | F28: 8668 | H28: 8521 | J28: 56 coups | M28: 25 coups | P28: 10 coups
A29: Vol. du moule (cm3) | D29: 2300 | F29: 2300 | H29: 2300 | J29: N° de la tare | L29: 25 | M29: N° de la tare | O29: 43 | P29: N° de la tare | R29: DB1
A30: r (g/cm3) | D30: =IF(D28<>0, (D28-D27)/D29, "") -> 2.2543478 | F30: =IF(F28<>0, (F28-F27)/F29*1, "") -> 2.1417391 | H30: =IF(H28<>0, (H28-H27)/H29*1, "") -> 2.0291304 | J30: M tare | L30: 34.8 | M30: M tare | O30: 23.6 | P30: M tare | R30: 40.5
A31: rd (g/cm3) | D31: =IF(D28<>0, D30/(1+C23*0.01), "") -> 2.1029887 | F31: =IF(F28<>0, F30/(1+E23*0.01), "") -> 1.9977936 | H31: =IF(H28<>0, H30/(1+G23*0.01), "") -> 1.8934572 | J31: Mh+tare | L31: 183.74 | M31: Mh+tare | O31: 143.9 | P31: Mh+tare | R31: 183.4
J32: Ms+tare | L32: 171.5 | M32: Ms+tare | O32: 133.7 | P32: Ms+tare | R32: 171.2
J33: w (%) | L33: =(L31-L32)/(L32-L30)*100 -> 8.9539137 | M33: w (%) | O33: =(O31-O32)/(O32-O30)*100 -> 9.2643052 | P33: w (%) | R33: =(R31-R32)/(R32-R30)*100 -> 9.3343535
J34: Gonflement
J35: 55 coups | L35: 25 coups | N35: 10 coups | P35: Moyenne
J36: Temps | K36: mm | L36: Temps | M36: mm | N36: Temps | O36: mm | P36: =AVERAGE(K37,K38,M37,M38,O37,O38) -> #DIV/0!
J37: 1 | L37: 1 | N37: 1
J38: 2 | L38: 2 | N38: 2
J40: RESULTATS
J41: 56 coups
...

Sheet CBR Crb (2)
G1: CBR | N1: Projet
N2: ETUDE
G3: RAPPORT
A5: Nom du projet : | D5: =' CBR Poinc'!D4:I4 -> Corniche Pont du Djoué | J5: Date prélèvement : | N5: -
A6: Site : | J6: Lieu de prélèvement : | N6: =' CBR Poinc'!N5:Q5 -> Puit 5 - 1ère couche
A7: Client : | J7: N° Dossier :
A8: Date de l'essai : | D8: =' CBR Poinc'!D7:I7 -> Du 20/12/2019 au 24/12/2019 | J8: Profondeur (m) : | N8: -
J9: Nature de l'échantillon: | N9: =' CBR Poinc'!N8:Q8 -> Sable Gréseux
A11: Essai | B11: I. CBR Immédiat | H11: Moule | I11: CBR | K11: x | M11: Matériau | O11: Non traité | Q11: x
B12: I.CBR Immersion | E12: x | I12: Nbre disques | K12: 2 | O12: Traité
B13: IPI | O13: Liant | P13: Neant
B14: Nombre de coups | H14: ρdOP (g/cm3) | J14: =' CBR Poinc'!J12 -> 2.103 | K14: =[1]CBR!K15 -> t/m3 | M14: rs | Q14: g/cm3
H15: wop | J15: =' CBR Poinc'!J13 -> 7.2 | K15: % | M15: Mesurée | P15: Estimée | Q15: x
A18: ESSAI PROCTOR MODIFIE | J18: ESSAI C.B.R. | M18: gd | O18: W% de | Q18: W% après 4j
D19: Essai Proctor | G19: Correction | J19: Nbre de coups | M19: (t/m³) | O19: MOULAGE
A20: yd OPM (t/m3) | D20: =J14 -> 2.103 | J20: 56 | M20: =C27 -> 2.1029887 | O20: =' CBR Poinc'!C23 -> 7.197333
A21: W OPM (%) | D21: =J15 -> 7.2 | J21: 25 | M21: =D27 -> 1.9977936 | O21: =' CBR Poinc'!E23 -> 7.2052233
A22: % > 20 mm | J22: 10 | M22: =E27 -> 1.8934572 | O22: =' CBR Poinc'!G23 -> 7.1653735
A25: Pts | C25: 56 | D25: 25 | E25: 10 | I25: OPM | K25: 0.98 | M25: 0.95 | O25: 0.94 | P25: 0.92 | Q25: 0.9
A26: CBR(%) | C26: =' CBR Poinc'!R42 -> 30.386406 | D26: =' CBR Poinc'!R46 -> 21.348742 | E26: =' CBR Poinc'!R50 -> 12.019541 | I26: CBR | M26: =T28 -> 21.4
A27: gd(t/m³) | C27: =' CBR Poinc'!D31 -> 2.1029887 | D27: =' CBR Poinc'!F31 -> 1.9977936 | E27: =' CBR Poinc'!H31 -> 1.8934572 | I27: gd(t/m³) | M27: =J14*0.95 -> 1.99785 | T27: CBR à 95%
T28: 21.4 | U28: =M27 -> 1.99785
T29: =T28 -> 21.4 | U29: 1.88
T31: =T28 -> 21.4 | U31: =U28 -> 1.99785
T32: 10 | U32: =U31 -> 1.99785
J46: Exécuté par | M46: NGOMA-NZAOU
A47: Remarques : | H47: B/ville, 24/12/2019
