Workbook
Name a: #REF!
Name a: #REF!
Name a: #REF!
Name B: #REF!
Name B: #REF!
Name B: #REF!
Name Compactação: #REF!
Name Compactação: #REF!
Name Compactação: #REF!
Name d: #REF!
Name d: #REF!
Name d: #REF!
Name da: #REF!
Name da: #REF!
Name da: #REF!
Name dd: #REF!
Name dd: #REF!
Name dd: #REF!
Name f: #REF!
Name f: #REF!
Name f: #REF!
Name H: #REF!
Name H: #REF!
Name H: #REF!
Name k: #REF!
Name k: #REF!
Name k: #REF!
Name kk: #REF!
Name kk: #REF!
Name kk: #REF!
Name Liquidez: #REF!
Name Liquidez: #REF!
Name Liquidez: #REF!
Name non: #REF!
Name non: #REF!
Name non: #REF!
Name o: #REF!
Name o: #REF!
Name o: #REF!
Name oi: #REF!
Name oi: #REF!
Name oi: #REF!
Name ou: #REF!
Name ou: #REF!
Name ou: #REF!
Name oui: #REF!
Name oui: #REF!
Name oui: #REF!
Name p: #REF!
Name p: #REF!
Name p: #REF!
Name Plasticidade: #REF!
Name Plasticidade: #REF!
Name Plasticidade: #REF!
Name Platicidade: #REF!
Name Platicidade: #REF!
Name Platicidade: #REF!
Name q: #REF!
Name q: #REF!
Name q: #REF!

Sheet PAGE RECAP  P1
C1: Bureau de Contrôle du Bâtiement et des Travaux Publics
M2: Technicien : NGOMA-NZAOU Drège
A3: PROVENANCE | E3: Corniche Brazzaville - Tronçon Fulbert YOULOU Pont du Djoué - Puit 3 - 1 ère couche
A4: DATE DE PRELEVEMENT | F4: 43808 | J4: DATE DES ESSAIS | N4: 43809 | S4: - | T4: 43827
A6: Nature de l'échantillon | F6: Sable limoneux gris
A7: Observations | F7: Profondeur 0,00 m - 0,50 m
A10: ESSAIS D'IDENTIFICATION | N10: Classification USHRB
A11: W.L. | D11: ='Limite '!K24 -> 27.84 | G11: Teneur en eau naturelle % | K11: ='Teneur en eau 2 P1 '!F41 -> 6.8478559
A12: W.P. | D12: ='Limite '!K25 -> 9.6831293 | G12: Poids spécifique ys (g/cm3) | K12: =PS!G42 -> 2.5584179 | N12: E.S(%) | R12: 36.6 | AB12: 300
A13: I.P. | D13: ='Limite '!K26 -> 18.156871 | G13: % 80 microns | K13: =E34 -> 24.866667 | N13: f x IP | R13: -
B15: Tamis | C15: Poids refus | D15: Pourcentage cumulé | E15: Tamisats
B16: <mm | AC16: 63
B17: 40 | C17: ='Granulo P1'!L23 -> 0 | D17: =(C17*100)/'Granulo P1'!C17:C18 -> 0 | E17: =100-D17 -> 100 | AC17: 50
B18: 31.5 | C18: ='Granulo P1'!L24 -> 0 | D18: =(C18*100)/'Granulo P1'!C17 -> 0 | E18: =100-D18 -> 100 | AC18: 40 | AD18: =E17 -> 100
B19: 20 | C19: ='Granulo P1'!L26 -> 0 | D19: =(C19*100)/'Granulo P1'!C17 -> 0 | E19: =100-D19 -> 100 | AC19: 31.5 | AD19: =E18 -> 100
B20: 10 | C20: ='Granulo P1'!L29 -> 0 | D20: =(C20*100)/'Granulo P1'!C17 -> 0 | E20: =100-D20 -> 100 | AC20: 20 | AD20: =E19 -> 100
B21: 6.3 | AC21: 10 | AD21: =E20 -> 100
B22: 5 | C22: ='Granulo P1'!L32 -> 4.1 | D22: =(C22*100)/'Granulo P1'!C17 -> 1.3666667 | E22: =100-D22 -> 98.633333 | AC22: 5 | AD22: =E22 -> 98.633333
B23: 4 | AC23: 2 | AD23: =E25 -> 96
B24: 2.5 | AC24: 1 | AD24: =E27 -> 93.733333
B25: 2 | C25: ='Granulo P1'!L36 -> 12 | D25: =(C25*100)/'Granulo P1'!C17 -> 4 | E25: =100-D25 -> 96 | AC25: 0.4 | AD25: =E29 -> 84
B26: 1.25 | AC26: 0.2 | AD26: =E31 -> 58.1
B27: 1 | C27: ='Granulo P1'!L39 -> 18.8 | D27: =(C27*100)/'Granulo P1'!C17 -> 6.2666667 | E27: =100-D27 -> 93.733333 | AC27: 0.1 | AD27: =E33 -> 29.533333
B28: 0.63 | AC28: 0.08 | AD28: =E34 -> 24.866667
B29: 0.4 | C29: ='Granulo P1'!L43 -> 48 | D29: =(C29*100)/'Granulo P1'!C17 -> 16 | E29: =100-D29 -> 84
B30: 0.315
B31: 0.2 | C31: ='Granulo P1'!L46 -> 125.7 | D31: =(C31*100)/'Granulo P1'!C17 -> 41.9 | E31: =100-D31 -> 58.1
B32: 0.16
B33: 0.1 | C33: ='Granulo P1'!L49 -> 211.4 | D33: =(C33*100)/'Granulo P1'!C17 -> 70.466667 | E33: =100-D33 -> 29.533333
B34: 0.08 | C34: ='Granulo P1'!L50 -> 225.4 | D34: =(C34*100)/'Granulo P1'!C17 -> 75.133333 | E34: =100-D34 -> 24.866667
A36: ESSAI PROCTOR MODIFIE | L36: Essai C.B.R. | O36: gd | Q36: W% de | S36: W% après 4j | U36: GONFLEMENT
D37: Essai Proctor | G37: Correction | L37: Nbre de coups | O37: (kN/m3) | Q37: MOULAGE | S37: IMBIBITION | U37: %
A38: yd OPM (T/m3) | D38: =Y54 -> 1.842 | L38: 56 | O38: =M44 -> 1.8422857 | S38: =' CBR Poinc'!L33 -> 9.0709583 | U38: 0
A39: W OPM (%) | D39: =X54 -> 7.3 | L39: 25 | O39: =N44 -> 1.7497149 | S39: =' CBR Poinc'!O33 -> 9.5063985 | U39: 0
A40: % > 20 mm | L40: 10 | O40: =O44 -> 1.6578686 | S40: =' CBR Poinc'!R33 -> 9.5496894 | U40: 0
A42: Pts | B42: 1 | C42: 2 | D42: 3 | E42: 4 | F42: 5 | G42: 6 | H42: OPM | L42: Pts | M42: 56 cps | N42: 25 cps | O42: 10 cps | R42: OPM | S42: 1 | T42: 0.98 | U42: 0.95 | V42: 0.9
A43: w% | B43: ='Proctor '!B41:C41 -> 4.1224917 | C43: ='Proctor '!D41 -> 6.0731824 | D43: ='Proctor '!F41 -> 8.3045222 | E43: ='Proctor '!H41 -> 10.146563 | F43: ='Proctor '!J41 -> 11.935936 | H43: =X54 -> 7.3 | L43: CBR | M43: ='CBR Crb (2)'!$C$26 -> 17.886674 | N43: ='CBR Crb (2)'!$D$26 -> 12.163514 | O43: ='CBR Crb (2)'!$E$26 -> 5.9113226 | R43: CBR | U43: =X47 -> 12.2
A44: gd | B44: ='Proctor '!B33:C33 -> 1.7920166 | C44: ='Proctor '!D33 -> 1.8337243 | D44: ='Proctor '!F33 -> 1.834945 | E44: ='Proctor '!H33 -> 1.7985061 | F44: ='Proctor '!J33 -> 1.749945 | H44: =Y54 -> 1.842 | L44: gd | M44: ='CBR Crb (2)'!$C$27 -> 1.8422857 | N44: ='CBR Crb (2)'!$D$27 -> 1.7497149 | O44: ='CBR Crb (2)'!$E$27 -> 1.6578686 | R44: gd | S44: =D38 -> 1.842 | T44: =0.98*D38 -> 1.80516 | U44: =Y47 -> 1.7499 | V44: =0.9*D38 -> 1.6578
X46: CBR à 95% | AA46: 1.5087425 | AC46: 1.7608815 | AE46: 1.8072857 | AG46: 1.7050329 | AI46: 1.6033512
X47: ='CBR Crb (2)'!T28 -> 12.2 | Y47: ='CBR Crb (2)'!U28 -> 1.7499
...

Sheet Teneur en eau 2 P1 
B1: PROCES-VERBAL D'ESSAIS
A2: Direction du Laboratoire | B2: Détermination de la teneur en eau pondérale des sols | N2: Direction du Laboratoire
B3: - Méthode par étuvage-
B4: NF P 94-050/ Septembre 1995
A6: Date de l'essai: | B6: 43809 | H6: Référence échantillon: | L6: Sable - Puit 3 - 1 ère couche
A9: Masse minimale de la prise d'essai:
A11: dm (µm) | B11: 400 | E11: 500 | H11: 630 | K11: 800 | N11: 1000
A12: Masse (g) | B12: 20 | E12: 50 | H12: 100 | K12: 150 | N12: 200
A14: dm (mm) | B14: 5 | C14: 6.3 | D14: 8 | E14: 10 | F14: 12.5 | G14: 16 | H14: 20 | I14: 25 | J14: 31.5 | K14: 40 | L14: 50 | M14: 63 | N14: 80 | O14: dm >80mm
A15: Masse (g) | B15: 0.3 | C15: 0.4 | D15: 0.5 | E15: 0.8 | F15: 1.2 | G15: 2 | H15: 3 | I15: 5 | J15: 8 | K15: 12 | L15: 20 | M15: 30 | N15: 50 | O15: m=6.106 dm 3,66
A18: Mesure de la teneur en eau
A20: ETUVE:
A21: Etuvage à :
E23: 50°C | M23: 105 °C
A25: TARE:
A27: Tare n°:……… | B27: X2/03 | H27: Masse de la tare:m1=……….. | M27: 33 | O27: 38.1 | P27: ....g.
A29: Masse avant étuvage : Prise de l'essai+tare: | H29: m2 = m+m1 =...……… | M29: 268.2 | O29: 226.3 | P29: ...g.
A31: Masse après étuvage, prise d'essai + tare : | K31: M3=…….….. | M31: 252.8 | O31: 214.5 | P31: …...g.
A33: TENEUR EN EAU:
A35: mw: masse de l'eau évaporée lors de l'étuvage
A36: md : masse des grains solides
S37: =(M29-M31)/(M31-M27)*100 -> 7.0063694 | T37: =(O29-O31)/(O31-O27)*100 -> 6.6893424
A41: W= | F41: =AVERAGE(S37:T37) -> 6.8478559 | I41: .…...…%
A46: Responsable de l'essai: | I46: Exécuté par
A50: BEANGE Grace

Sheet Granulo P1
B1: PROCES-VERBAL D'ESSAIS | L1: Référence: | N1: :FEE/310/18
A2: Direction du Laboratoire | B2: Sols : reconnaissance et essais Analyse granulométrique : Méthode par tamisage à sec après lavage | L2: Indice | N2: :0 1
L3: Date appl | N3: :30-10-2018
B4: NF P 94-056/ Mars 1996 | L4: Page | N4: : 1/1
A6: Date de l'essai: | B6: 43813 | F6: Référence échantillon: | K6: Sable Gris - Puit 3 - 1 ère couche
A9: Masse minimale de la prise d'essai:
A12: dm (mm) | B12: 5 | C12: 6.3 | D12: 8 | E12: 10 | F12: 12.5 | G12: 16 | H12: 20 | I12: 25 | J12: 31.5 | K12: 40 | L12: 63 | M12: 80 | N12: dm >80mm
A13: Masse (g) | B13: 0.3 | C13: 0.4 | D13: 0.5 | E13: 0.8 | F13: 1.2 | G13: 2 | H13: 3 | I13: 5 | J13: 8 | K13: 12 | L13: 30 | M13: 50 | N13: m=6.106 dm 3,66
A15: Matériau | B15: Masse de la prisse d'essai | E15: Tamis | H15: Masse refus mesuré (g) | L15: Masse refus R cumulé (g) | N15: Pourcentage massique
A17: dm= mm | B17: m= | C17: 300 | D17: g | E17: mm | F17: µm | H17: r i | J17: R | N17: Refus cumulé r | O17: Tamisât cumulé p
A19: Partage au tamis dc : | D19: ..mm | E19: 100
E20: 80
A21: Masse sèche du refus au tamis dc: | E21: 63
A22: RC=………………… | D22: …….g | E22: 50
A23: Masse passant au tamis dc: | E23: 40 | L23: =J23 -> 0 | N23: =L23/C17*100 -> 0 | O23: =100-N23 -> 100
A24: mh= ………………. | D24: …….g | E24: 31.5 | L24: =L23+J24 -> 0 | N24: =L24/C17*100 -> 0 | O24: =100-N24 -> 100
A25: Part (1) sur tamisat au tamis dc | B25: Masse humide: | E25: 25
B26: Mh1 =.. | D26: ……..g | E26: 20 | J26: 0 | L26: =J26+L24 -> 0 | N26: =L26/C17*100 -> 0 | O26: =100-N26 -> 100
B27: Masse sèche: | E27: 16
B28: Ms1 | D28: ..…..g | E28: 12.5
A29: Part (2) sur tamisat au tamis dc | B29: Masse humide: | E29: 10 | J29: 0 | L29: =J29+L26 -> 0 | N29: =L29/C17*100 -> 0 | O29: =100-N29 -> 100
B30: Mh1 =.. | D30: ……..g | E30: 8
B31: Masse sèche: | E31: 6.3
B32: Ms1… | D32: ……..g | E32: 5 | J32: 4.1 | L32: =J32+L29 -> 4.1 | N32: =L32/C17*100 -> 1.3666667 | O32: =100-N32 -> 98.633333
A33: Masse sèche totale: | E33: 4
A34: ms=Rc+mh.ms1/mh1=…… | D34: ……..g | E34: 3.15
A35: Coefficient multiplicateur sur le refus au tamis de 80µm: | E35: 2.5
E36: 2 | J36: 7.9 | L36: =J36+L32 -> 12 | N36: =L36/C17*100 -> 4 | O36: =100-N36 -> 96
A37: b=mh/mh2:……..……….. | D37: ………. | E37: 1.6
A38: Refus cumulé R = RC + br1 | E38: 1.25
A39: Masse (80µm,dc):ms4= Prélèvement 2 | D39: ……..g | E39: 1 | J39: 6.8 | L39: =J39+L36 -> 18.8 | N39: =L39/C17*100 -> 6.2666667 | O39: =100-N39 -> 93.733333
E40: 0.8 | F40: 800
A41: Masse passant à 80µm de lafraction (80µm,dc ): | E41: 0.63 | F41: 630
E42: 0.5 | F42: 500
A43: Sur part(2)ms3 =……………. | D43: ……g | E43: 0.4 | F43: 400 | J43: 29.2 | L43: =J43+L39 -> 48 | N43: =L43/C17*100 -> 16 | O43: =100-N43 -> 84
E44: 0.315 | F44: 315
A45: Pourcentage | C45: Refus: | E45: 0.25 | F45: 250
C46: R = 100 R/ms | E46: 0.2 | F46: 200 | J46: 77.7 | L46: =J46+L43 -> 125.7 | N46: =L46/C17*100 -> 41.9 | O46: =100-N46 -> 58.1
C47: De tamisat: | E47: 0.16 | F47: 160
C48: 100(1-R/ms) | E48: 0.125 | F48: 125
...

Sheet Courbe P1 (2)
B1: PROCES-VERBAL D'ESSAIS | L1: Référence: | N1: :FEE/310/18
A2: Direction du Laboratoire | B2: Sols : reconnaissance et essais Analyse granulométrique : Méthode par tamisage à sec après lavage | L2: Indice | N2: :0 1
L3: Date appl | N3: :30-10-2018
B4: Effectuée conformement à la norme NF P 94-056/ Mars 1996 | L4: Page | N4: : 1/1
A6: Date de l'essai: | B6: ='Granulo P1'!B6:E6 -> 43813 | G6: Référence échantillon: | L6: ='Granulo P1'!K6 -> Sable Gris - Puit 3 - 1 ère couche
A9: Masse minimale de la prise d'essai:
A12: dm (mm) | B12: 5 | C12: 6.3 | D12: 8 | E12: 10 | F12: 12.5 | G12: 16 | H12: 20 | I12: 25 | J12: 31.5 | K12: 40 | L12: 63 | M12: 80 | N12: dm >80mm
A13: Masse (g) | B13: 0.3 | C13: 0.4 | D13: 0.5 | E13: 0.8 | F13: 1.2 | G13: 2 | H13: 3 | I13: 5 | J13: 8 | K13: 12 | L13: 30 | M13: 50 | N13: m=6.106 dm 3,66
T19: 40 | U19: ='Granulo P1'!O23 -> 100
T20: 31.5 | U20: ='Granulo P1'!O24 -> 100
T21: 20 | U21: ='Granulo P1'!O26 -> 100
T22: 10 | U22: ='Granulo P1'!O29 -> 100
T23: 5 | U23: ='Granulo P1'!O32 -> 98.633333
T24: 2 | U24: ='Granulo P1'!O36 -> 96
T25: 1 | U25: ='Granulo P1'!O39 -> 93.733333 | W25: 99.9
T26: 0.4 | U26: ='Granulo P1'!O43 -> 84 | W26: 83.633333
T27: 0.2 | U27: ='Granulo P1'!O46 -> 58.1 | W27: 41.6
T28: 0.1 | U28: ='Granulo P1'!O49 -> 29.533333 | W28: 11.966667
T29: 0.08 | U29: ='Granulo P1'!O50 -> 24.866667 | W29: 8.0333333

Sheet Limite 
I1: DOSSIER: | K1: 00/00
A2: Direction du Laboratoire | I2: DATE: | K2: 43801
I3: OPERATEUR: | K3: Claire
C5: PROVENANCE: | I5: PREPARATION: à sèc
C6: ECHANTILLON:
A7: APPAREIL | B7: Casagrande | C7: NATURE:
A8: NOMBRE DE COUPS | C8: LIMITE DE LIQUIDITE | I8: LIMITE DE PLASTICITE
C9: 16 | D9: 20 | E9: 24 | F9: 28 | G9: 32 | H9: 35
A10: NUMERO DE LA TARE | C10: 44 | D10: 465 | E10: 528 | F10: 85 | G10: 420 | I10: 477 | J10: K | K10: 402
A11: POIDS TOTAL HUMIDE | C11: 23.58 | D11: 24.27 | E11: 24.34 | F11: 24.82 | G11: 20.74 | I11: 16.22 | J11: 17.42 | K11: 17.56
A12: POIDS TOTAL SEC | C12: 20.16 | D12: 20.42 | E12: 20.73 | F12: 21.25 | G12: 18.11 | I12: 15.48 | J12: 16.54 | K12: 16.74
A13: POIDS DE LA TARE | C13: 8.49 | D13: 6.99 | E13: 7.89 | F13: 8.22 | G13: 8.25 | I13: 7.76 | J13: 7.92 | K13: 7.88
A14: POIDS D'EAU | C14: =C11-C12 -> 3.42 | D14: =D11-D12 -> 3.85 | E14: =E11-E12 -> 3.61 | F14: =F11-F12 -> 3.57 | G14: =G11-G12 -> 2.63 | I14: =I11-I12 -> 0.74 | J14: =J11-J12 -> 0.88 | K14: =K11-K12 -> 0.82
A15: POIDS NET SEC | C15: =C12-C13 -> 11.67 | D15: =D12-D13 -> 13.43 | E15: =E12-E13 -> 12.84 | F15: =F12-F13 -> 13.03 | G15: =G12-G13 -> 9.86 | I15: =I12-I13 -> 7.72 | J15: =J12-J13 -> 8.62 | K15: =K12-K13 -> 8.86
A16: TENEUR D'EAU | C16: =(C14/C15)*100 -> 29.305913 | D16: =(D14/D15)*100 -> 28.667163 | E16: =(E14/E15)*100 -> 28.115265 | F16: =(F14/F15)*100 -> 27.398312 | G16: =(G14/G15)*100 -> 26.673428 | I16: =(I14/I15)*100 -> 9.5854922 | J16: =(J14/J15)*100 -> 10.208817 | K16: =(K14/K15)*100 -> 9.255079
L20: X | M20: 27.84 | N20: 25
L21: Y | M21: =M20 -> 27.84 | N21: 14
M23: 12 | N23: 25
J24: L.L | K24: 27.84 | M24: 27.84 | N24: 25
J25: L.P | K25: =AVERAGE(I16:K16) -> 9.6831293
J26: I.P | K26: =K24-K25 -> 18.156871

Sheet PS
A11: POIDS SPECIFIQUE
G13: Date : 18/12/2019
E15: Expérimentateur :BEANGE Grace
A16: Nature :Sable Gris ,Profondeur 0,00 m - 0,50 m, Puit 3 - 1 ère couche
A17: N° PYCNOMETRE | G17: 8 | H17: 4
A18: Poids Pycnomètre vide = PO | G18: 259.8 | H18: 289.7
A20: Poids Pycnomètre + Matériaux Sec = P2 | G20: 559.8 | H20: 589.6
A22: Poids Pycnomètre + Matériaux +Eau =P3 | G22: 981.1 | H22: 1000.3
A24: Poids Pycnomètre + Eau =P1 | G24: 797.3 | H24: 818.7
A28: Volume Pycnomètre = P1-P0 = P4 | G28: =G24-G18 -> 537.5 | H28: =H24-H18 -> 529
A30: Volume Matériaux Net Sec = P2-P0 = P5 | G30: =G20-G18 -> 300 | H30: =H20-H18 -> 299.9
A32: Volume d'Eau Restant = P3-P2= P6 | G32: =G22-G20 -> 421.3 | H32: =H22-H20 -> 410.7
A34: Volume Matériaux = P4-P6= VM* | G34: =G28-G32 -> 116.2 | H34: =H28-H32 -> 118.3
A38: Poids Spécifique | G38: =G30/G34 -> 2.5817556 | H38: =H30/H34 -> 2.5350803
A42: Moyenne | G42: =AVERAGE(G38,H38,I38) -> 2.5584179
A44: Observation:
A46: Opérateur: | E46: Chargé d'affaire:

Sheet Proctor 
B1: Bureau de Contrôle du Bâtiment et des Travaux Publics(B.C.B.T.P) | J1: Enregistrement:
B2: Fiche d'Essai | J2: Page:1/1
J3: Mise à jour:
A5: N° d'affaire | B5: DETERMINATION DES REFERENCES DE COMPACTAGE
B6: D'UN MATERIAU
B7: Essai Proctor normal-Essai Proctor modifié
A10: NORME: NF P94-093 Octobre 1999
A11: Localisation du chantier: Corniche pont du Djoué
A12: Nom du client: | E12: Nature de materiaux: Sable Gris
A13: N° de reception: | E13: Utilisation:
A14: Date de reception: | E14: Mode de prélevement: Manuel
A15: Provenance:P 3 - 3ème couche | E15: Prélevement effectué: BCBTP
A17: PROCTOR | C17: NORMAL | H17: MODIFIE | K17: X
C18: Moule Proctor | E18: Moule CBR | H18: Moule Proctor | J18: Moule CBR
A19: Masse de la dame | C19: 2490g | H19: 4535g
A20: Diamètre du mouton | C20: 51mm | H20: 51mm
A21: Hauteur de chute | C21: 305mm | H21: 457mm
A22: Nombre de couches | C22: 3 | H22: 5
A23: Nombre de coups par couche | C23: 25 | E23: 56 | H23: 25 | J23: 56
A24: Diamètre maxi(mm) | B24: 1 | E24: Pourcentage de refus au tamis 20mm | I24: 0
A25: DENSITE
A26: N° Moule | B26: B | D26: B | F26: B | H26: B | J26: B
A27: Eau de moulage(%) | B27: 4 | D27: 6 | F27: 8 | H27: 10 | J27: 12
A28: Poids du moule | B28: 4034 | D28: 4034 | F28: 4034 | H28: 4034 | J28: 4034
A29: Poids moule+ sol humide | B29: 5801 | D29: 5876 | F29: 5916 | H29: 5910 | J29: 5889
A30: Poids net humide | B30: =B29-B28 -> 1767 | D30: =D29-D28 -> 1842 | F30: =F29-F28 -> 1882 | H30: =H29-H28 -> 1876 | J30: =J29-J28 -> 1855
A31: Volume du moule | B31: 947 | D31: 947 | F31: 947 | H31: 947 | J31: 947
A32: Densité humide | B32: =B30*1/B31 -> 1.8658923 | D32: =D30*1/D31 -> 1.9450898 | F32: =F30*1/F31 -> 1.9873284 | H32: =H30*1/H31 -> 1.9809926 | J32: =J30*1/J31 -> 1.9588173
A33: Densité sèche | B33: =(B32)*100/(100+B41) -> 1.7920166 | D33: =(D32)*100/(100+D41) -> 1.8337243 | F33: =(F32)*100/(100+F41) -> 1.834945 | H33: =(H32)*100/(100+H41) -> 1.7985061 | J33: =(J32)*100/(100+J41) -> 1.749945
A34: TENEUR EN EAU
A35: N° Tare | B35: B102 | C35: DL | D35: B102 | E35: DL | F35: B4 | G35: B47 | H35: A3 | I35: B' | J35: DB3 | K35: 11'
A36: Poids de la tare | B36: 15.7 | C36: 34.7 | D36: 15.7 | E36: 34.7 | F36: 35.5 | G36: 34.7 | H36: 23.2 | I36: 15.3 | J36: 33.4 | K36: 24.2
A37: Poids tare+ sol humide | B37: 174.4 | C37: 258.6 | D37: 174.4 | E37: 258.6 | F37: 213.4 | G37: 232.2 | H37: 167.8 | I37: 143.2 | J37: 264.8 | K37: 270.1
A38: Poids tare+ sol sec | B38: 168 | C38: 249.9 | D38: 165.3 | E38: 245.8 | F38: 199.9 | G38: 216.9 | H38: 154.5 | I38: 131.4 | J38: 240.2 | K38: 243.8
A39: Poids sec | B39: =B38-B36 -> 152.3 | C39: =C38-C36 -> 215.2 | D39: =D38-D36 -> 149.6 | E39: =E38-E36 -> 211.1 | F39: =F38-F36 -> 164.4 | G39: =G38-G36 -> 182.2 | H39: =H38-H36 -> 131.3 | I39: =I38-I36 -> 116.1 | ... K39: =K38-K36 -> 219.6
A40: Teneur en eau | B40: =((B37)-(B38))*100/B39 -> 4.2022324 | C40: =((C37)-(C38))*100/C39 -> 4.0427509 | D40: =((D37)-(D38))*100/D39 -> 6.0828877 | E40: =((E37)-(E38))*100/E39 -> 6.063477 | F40: =((F37)-(F38))*100/F39 -> 8.2116788 | G40: =((G37)-(G38))*100/G39 -> 8.3973655 | H40: =((H37)-(H38))*100/H39 -> 10.129474 | I40: =((I37)-(I38))*100/I39 -> 10.163652 | ... K40: =((K37)-(K38))*100/K39 -> 11.976321
A41: Teneur en eau moyenne | B41: =AVERAGE(B40:C40) -> 4.1224917 | D41: =AVERAGE(D40:E40) -> 6.0731824 | F41: =AVERAGE(F40:G40) -> 8.3045222 | H41: =AVERAGE(H40:I40) -> 10.146563 | J41: =AVERAGE(J40:K40) -> 11.935936
A43: Densité OPM(t/m³) | B43: =O52 -> 1.842 | F43: Paramètres après correction | I43: =B43 -> 1.842 | K43: t/m³
A44: Teneur en eau OPM(%) | B44: =N52 -> 7.3 | I44: =B44 -> 7.3 | K44: %
N51: w | O51: den
...

Sheet  CBR Poinc
G1: ESSAI CBR | N1: Projet
N2: Etude
G3: Norme NF P 94-078
A4: Nom du projet : | D4: Corniche Pont du Djoué | J4: Date prélèvement :
A5: Site : | J5: Lieu de prélèvement : | N5: Puit 3 - 1 ère couche
A6: Client : | J6: N° Dossier :
A7: Date de l'essai : | D7: Du 10/12/2019 au 28/12/2019 | J7: Profondeur (m) :
J8: Nature de l'échantillon: | N8: Sable Gris
A9: Essai | B9: I. CBR Immédiat | H9: Moule | I9: CBR | K9: x | M9: Matériau | O9: Non traité | Q9: x
B10: I.CBR Immersion | E10: x | I10: Nbre disques | K10: 2 | O10: Traité
B11: IPI | O11: Liant | P11: Neant
B12: Durée immersion | E12: 96h | H12: ρdOP (g/cm3) | J12: ='Proctor '!B43 -> 1.842 | K12: t/m3 | M12: Denité sèche | P12: =J12 -> 1.842 | Q12: g/cm3
H13: wop | J13: ='Proctor '!B44 -> 7.3 | K13: % | M13: Mesurée | P13: Estimée | Q13: x
A14: Essai après imbibition
A15: Teneur en eau de compactage | K15: Poinconnement
A16: Coups | C16: 56 | E16: 25 | G16: 10 | J16: 56 coups | M16: 25 coups | P16: 10 coups
A17: Essai N° | C17: 1 | D17: 2 | E17: 1 | F17: 2 | G17: 1 | H17: 2 | J17: Enf,(mm) | K17: Lecture | L17: Effort (kN) | M17: Enf,(mm) | N17: Lecture | O17: Effort (kN) | P17: Enf,(mm) | Q17: Lecture | R17: Effort (kN)
A18: N° de la tare | C18: 38 | D18: 15 | E18: X3 | F18: X2 | G18: B21 | H18: DB4 | J18: 0 | K18: 0 | L18: 0 | M18: 0 | N18: 0 | O18: 0 | P18: 0 | Q18: 0 | R18: 0
A19: tare | C19: 36.8 | D19: 35 | E19: 33.3 | F19: 33.1 | G19: 34.9 | H19: 23.4 | J19: 0.5 | K19: 0.4 | L19: =((K19*9.8977)-0.3056)*10 -> 36.5348 | M19: 0.5 | N19: 0.22 | O19: =((N19*9.8977)-0.3056)*10 -> 18.71894 | P19: 0.5 | Q19: 0.1 | R19: =((Q19*9.8977)-0.3056)*10 -> 6.8417
A20: Mh+tare | C20: 209.4 | D20: 199.6 | E20: 209.6 | F20: 227.6 | G20: 222.3 | H20: 173.2 | J20: 1 | K20: 0.85 | L20: =((K20*9.8977)-0.3056)*10 -> 81.07445 | M20: 1 | N20: 0.44 | O20: =((N20*9.8977)-0.3056)*10 -> 40.49388 | P20: 1 | Q20: 0.28 | R20: =((Q20*9.8977)-0.3056)*10 -> 24.65756
A21: Ms + tare | C21: 197.7 | D21: 188.4 | E21: 197.6 | F21: 214.3 | G21: 209.6 | H21: 163 | J21: 1.5 | K21: 1.22 | L21: =((K21*9.8977)-0.3056)*10 -> 117.69594 | M21: 1.5 | N21: 0.76 | O21: =((N21*9.8977)-0.3056)*10 -> 72.16652 | P21: 1.5 | Q21: 0.35 | R21: =((Q21*9.8977)-0.3056)*10 -> 31.58595
A22: w (%) | C22: =IF(C21<>0, (C20-C21)/(C21-C19)*100, "") -> 7.2715973 | D22: =(D20-D21)/(D21-D19)*100 -> 7.3011734 | E22: =IF(E21<>0, (E20-E21)/(E21-E19)*100, "") -> 7.3037127 | F22: =(F20-F21)/(F21-F19)*100 -> 7.3399558 | G22: =(G20-G21)/(G21-G19)*100 -> 7.269605 | H22: =(H20-H21)/(H21-H19)*100 -> 7.3065903 | J22: 2 | K22: 1.8 | L22: =((K22*9.8977)-0.3056)*10 -> 175.1026 | M22: 2 | N22: 1.22 | O22: =((N22*9.8977)-0.3056)*10 -> 117.69594 | P22: 2 | Q22: 0.51 | R22: =((Q22*9.8977)-0.3056)*10 -> 47.42227
A23: w Moyenne | C23: =AVERAGE(C22:D22) -> 7.2863853 | E23: =AVERAGE(E22:F22) -> 7.3218343 | G23: =AVERAGE(G22:H22) -> 7.2880976 | J23: 2.5 | K23: 2.13 | L23: =((K23*9.8977)-0.3056)*10 -> 207.76501 | M23: 2.5 | N23: 1.59 | O23: =((N23*9.8977)-0.3056)*10 -> 154.31743 | P23: 2.5 | Q23: 0.58 | R23: =((Q23*9.8977)-0.3056)*10 -> 54.35066
A24: % wop | C24: =C23/J13*100 -> 99.813498 | E24: =E23/J13*100 -> 100.2991 | G24: =G23/J13*100 -> 99.836954 | J24: 5 | K24: 3.75 | L24: =((K24*9.8977)-0.3056)*10 -> 368.10775 | M24: 5 | N24: 2.56 | O24: =((N24*9.8977)-0.3056)*10 -> 250.32512 | P24: 5 | Q24: 1.26 | R24: =((Q24*9.8977)-0.3056)*10 -> 121.65502
A25: Densité sèche de compactage | J25: 6 | K25: 4.69 | L25: =((K25*9.8977)-0.3056)*10 -> 461.14613 | M25: 6 | N25: 3.09 | O25: =((N25*9.8977)-0.3056)*10 -> 302.78293 | P25: 6 | Q25: 1.71 | R25: =((Q25*9.8977)-0.3056)*10 -> 166.19467
A26: N° du moule | D26: NK' | F26: co | H26: E | J26: 10 | K26: 7.56 | L26: =((K26*9.8977)-0.3056)*10 -> 745.21012 | M26: 10 | N26: 5.6 | O26: =((N26*9.8977)-0.3056)*10 -> 551.2152 | P26: 10 | Q26: 2.7 | R26: =((Q26*9.8977)-0.3056)*10 -> 264.1819
A27: Moule (g) | D27: 3820 | F27: 3800 | H27: 3830
A28: Moule + sol (g) | D28: 8366 | F28: 8119 | H28: 7921 | J28: 56 coups | M28: 25 coups | P28: 10 coups
A29: Vol. du moule (cm3) | D29: 2300 | F29: 2300 | H29: 2300 | J29: N° de la tare | L29: B3 | M29: N° de la tare | O29: 43 | P29: N° de la tare | R29: 44
A30: r (g/cm3) | D30: =IF(D28<>0, (D28-D27)/D29, "") -> 1.9765217 | F30: =IF(F28<>0, (F28-F27)/F29*1, "") -> 1.8778261 | H30: =IF(H28<>0, (H28-H27)/H29*1, "") -> 1.7786957 | J30: M tare | L30: 34.8 | M30: M tare | O30: 23.6 | P30: M tare | R30: 40.5
A31: rd (g/cm3) | D31: =IF(D28<>0, D30/(1+C23*0.01), "") -> 1.8422857 | F31: =IF(F28<>0, F30/(1+E23*0.01), "") -> 1.7497149 | H31: =IF(H28<>0, H30/(1+G23*0.01), "") -> 1.6578686 | J31: Mh+tare | L31: 183.9 | M31: Mh+tare | O31: 143.4 | P31: Mh+tare | R31: 181.6
J32: Ms+tare | L32: 171.5 | M32: Ms+tare | O32: 133 | P32: Ms+tare | R32: 169.3
J33: w (%) | L33: =(L31-L32)/(L32-L30)*100 -> 9.0709583 | M33: w (%) | O33: =(O31-O32)/(O32-O30)*100 -> 9.5063985 | P33: w (%) | R33: =(R31-R32)/(R32-R30)*100 -> 9.5496894
J34: Gonflement
J35: 55 coups | L35: 25 coups | N35: 10 coups | P35: Moyenne
J36: Temps | K36: mm | L36: Temps | M36: mm | N36: Temps | O36: mm | P36: =AVERAGE(K37,K38,M37,M38,O37,O38) -> #DIV/0!
J37: 1 | L37: 1 | N37: 1
J38: 2 | L38: 2 | N38: 2
J40: RESULTATS
J41: 56 coups
...

Sheet CBR Crb (2)
G1: CBR | N1: Projet
N2: ETUDE
G3: RAPPORT
A5: Nom du projet : | D5: =' CBR Poinc'!D4:I4 -> Corniche Pont du Djoué | J5: Date prélèvement : | N5: -
A6: Site : | J6: Lieu de prélèvement : | N6: =' CBR Poinc'!N5:Q5 -> Puit 3 - 1 ère couche
A7: Client : | J7: N° Dossier :
A8: Date de l'essai : | D8: =' CBR Poinc'!D7:I7 -> Du 10/12/2019 au 28/12/2019 | J8: Profondeur (m) : | N8: -
J9: Nature de l'échantillon: | N9: =' CBR Poinc'!N8:Q8 -> Sable Gris
A11: Essai | B11: I. CBR Immédiat | H11: Moule | I11: CBR | K11: x | M11: Matériau | O11: Non traité | Q11: x
B12: I.CBR Immersion | E12: x | I12: Nbre disques | K12: 2 | O12: Traité
B13: IPI | O13: Liant | P13: Neant
B14: Nombre de coups | H14: ρdOP (g/cm3) | J14: =' CBR Poinc'!J12 -> 1.842 | K14: =[1]CBR!K15 -> t/m3 | M14: rs | Q14: g/cm3
H15: wop | J15: =' CBR Poinc'!J13 -> 7.3 | K15: % | M15: Mesurée | P15: Estimée | Q15: x
A18: ESSAI PROCTOR MODIFIE | J18: ESSAI C.B.R. | M18: gd | O18: W% de | Q18: W% après 4j
D19: Essai Proctor | G19: Correction | J19: Nbre de coups | M19: (t/m³) | O19: MOULAGE
A20: yd OPM (t/m3) | D20: =J14 -> 1.842 | J20: 56 | M20: =C27 -> 1.8422857 | O20: =' CBR Poinc'!C23 -> 7.2863853
A21: W OPM (%) | D21: =J15 -> 7.3 | J21: 25 | M21: =D27 -> 1.7497149 | O21: =' CBR Poinc'!E23 -> 7.3218343
A22: % > 20 mm | J22: 10 | M22: =E27 -> 1.6578686 | O22: =' CBR Poinc'!G23 -> 7.2880976
A25: Pts | C25: 56 | D25: 25 | E25: 10 | I25: OPM | K25: 0.98 | M25: 0.95 | O25: 0.94 | P25: 0.92 | Q25: 0.9
A26: CBR(%) | C26: =' CBR Poinc'!R42 -> 17.886674 | D26: =' CBR Poinc'!R46 -> 12.163514 | E26: =' CBR Poinc'!R50 -> 5.9113226 | I26: CBR | M26: =T28 -> 12.2
A27: gd(t/m³) | C27: =' CBR Poinc'!D31 -> 1.8422857 | D27: =' CBR Poinc'!F31 -> 1.7497149 | E27: =' CBR Poinc'!H31 -> 1.6578686 | I27: gd(t/m³) | M27: =J14*0.95 -> 1.7499 | T27: CBR à 95%
T28: 12.2 | U28: =M27 -> 1.7499
T29: 12.2 | U29: 1.64
T31: =T28 -> 12.2 | U31: =U28 -> 1.7499
T32: 4 | U32: =U31 -> 1.7499
J46: Exécuté par | M46: NGOMA-NZAOU
A47: Remarques : | H47: B/ville, 23/08/2019
