Workbook
Name a: #REF!
Name a: #REF!
Name B: #REF!
Name Compactação: #REF!
Name d: #REF!
Name d: #REF!
Name da: #REF!
Name da: #REF!
Name dd: #REF!
Name dd: #REF!
Name f: #REF!
Name f: #REF!
Name H: #REF!
Name H: #REF!
Name k: #REF!
Name k: #REF!
Name kk: #REF!
Name kk: #REF!
Name Liquidez: #REF!
Name non: #REF!
Name non: #REF!
Name o: #REF!
Name o: #REF!
Name oi: #REF!
Name oi: #REF!
Name ou: #REF!
Name ou: #REF!
Name oui: #REF!
Name oui: #REF!
Name p: #REF!
Name p: #REF!
Name Plasticidade: #REF!
Name Platicidade: #REF!
Name q: #REF!
Name q: #REF!
Name sa: #REF!
Name sa: #REF!
Name sandro: #REF!
Name sandro: #REF!
Name sq: #REF!
Name sq: #REF!
Name ss: #REF!
Name ss: #REF!
Name w: #REF!
Name w: #REF!
Name xa: #REF!
Name xa: #REF!

Sheet PAGE RECAP  P1 (2)
C1: Bureau de Contrôle du Bâtiement et des Travaux Publics
M2: Technicien : NGOMA-NZAOU Drège
A3: PROVENANCE | E3: Corniche Brazzaville - Tronçon Fulbert YOULOU Pont du Djoué - Puit 2 - 2 ème couche
A4: DATE DE PRELEVEMENT | F4: 43808 | J4: DATE DES ESSAIS | N4: 43809 | S4: - | T4: 43827
A6: Nature de l'échantillon | F6: TVC (Grès de l'Inkisi)
A7: Observations | F7: Profondeur 0,35 m - 0,40 m
A10: ESSAIS D'IDENTIFICATION | N10: Classification USHRB
A11: W.L. | D11: / | G11: Teneur en eau naturelle % | K11: ='Teneur en eau 2 P1 '!F41 -> 11.154653
A12: W.P. | D12: / | G12: Poids spécifique ys (g/cm3) | K12: 2.53 | N12: E.S(%) | R12: 29 | AB12: 300
A13: I.P. | D13: / | G13: % 80 microns | K13: ='Granulo P1'!O50 -> 21.4 | N13: f x IP | R13: /
B15: Tamis | D15: Poids cumulé | E15: Tamisats
B16: <mm
B17: 40
B18: 31.5
B19: 20 | D19: ='Granulo P1'!N26 -> 0 | E19: ='Granulo P1'!O26 -> 100
B20: 10 | AB20: 63
B21: 6.3 | AB21: 50
B22: 5 | D22: ='Granulo P1'!N32 -> 9.6666667 | E22: ='Granulo P1'!O32 -> 90.333333 | AB22: 40
B23: 4 | AB23: 31.5
B24: 2.5 | AB24: 20
B25: 2 | D25: ='Granulo P1'!N36 -> 10.9 | E25: ='Granulo P1'!O36 -> 89.1 | AB25: 10 | AC25: 100
B26: 1.25 | AB26: 5 | AC26: 100
B27: 1 | D27: ='Granulo P1'!L39 -> 37.9 | E27: =100-((D27*100)/AB12) -> 87.366667 | AB27: 2 | AC27: 100 | AE27: =E27 -> 87.366667
B28: 0.63 | AB28: 1 | AC28: =E27 -> 87.366667 | AE28: =E29 -> 71.4
B29: 0.4 | D29: ='Granulo P1'!L43 -> 85.8 | E29: =100-((D29*100)/AB12) -> 71.4 | AB29: 0.4 | AC29: =E29 -> 71.4 | AE29: =E31 -> 45.833333
B30: 0.315 | AB30: 0.2 | AC30: =E31 -> 45.833333 | AE30: =E33 -> 24.133333
B31: 0.2 | D31: ='Granulo P1'!L46 -> 162.5 | E31: =100-((D31*100)/AB12) -> 45.833333 | AB31: 0.1 | AC31: =E33 -> 24.133333 | AE31: 5.7666667
B32: 0.16 | AB32: 0.08 | AC32: =E34 -> 21.4
B33: 0.1 | D33: ='Granulo P1'!L49 -> 227.6 | E33: =100-((D33*100)/AB12) -> 24.133333
B34: 0.08 | D34: ='Granulo P1'!L50 -> 235.8 | E34: =100-((D34*100)/AB12) -> 21.4
A36: Le Chef de Division Essais, | K36: Le Directeur du Laboratoire,
A38: Matériaux et Expertise
A43: Eric ONDZOULOU | K43: Jean Richard NGAMBIE
X46: CBR à 95%
X47: 4.73 | Y47: 1.65
X48: =X47 -> 4.73 | Y48: 1.5
X50: 0 | Y50: =Y47 -> 1.65
X51: 4.75 | Y51: =Y50 -> 1.65
X53: OPM
X54: 15.34 | Y54: 1.742
...

Sheet Teneur en eau 2 P1 
B1: PROCES-VERBAL D'ESSAIS
A2: Direction du Laboratoire | B2: Détermination de la teneur en eau pondérale des sols | N2: Direction du Laboratoire
B3: - Méthode par étuvage-
B4: NF P 94-050/ Septembre 1995
A6: Date de l'essai: | B6: 43809 | H6: Référence échantillon: | L6: Puit 2 - 2ème couche
A9: Masse minimale de la prise d'essai:
A11: dm (µm) | B11: 400 | E11: 500 | H11: 630 | K11: 800 | N11: 1000
A12: Masse (g) | B12: 20 | E12: 50 | H12: 100 | K12: 150 | N12: 200
A14: dm (mm) | B14: 5 | C14: 6.3 | D14: 8 | E14: 10 | F14: 12.5 | G14: 16 | H14: 20 | I14: 25 | J14: 31.5 | K14: 40 | L14: 50 | M14: 63 | N14: 80 | O14: dm >80mm
A15: Masse (g) | B15: 0.3 | C15: 0.4 | D15: 0.5 | E15: 0.8 | F15: 1.2 | G15: 2 | H15: 3 | I15: 5 | J15: 8 | K15: 12 | L15: 20 | M15: 30 | N15: 50 | O15: m=6.106 dm 3,66
A18: Mesure de la teneur en eau
A20: ETUVE:
A21: Etuvage à :
E23: 50°C | M23: 105 °C
A25: TARE:
A27: Tare n°:……… | B27: B4/B27 | H27: Masse de la tare:m1=……….. | M27: 35.7 | O27: 35 | P27: ....g.
A29: Masse avant étuvage : Prise de l'essai+tare: | H29: m2 = m+m1 =...……… | M29: 252.9 | O29: 254.3 | P29: ...g.
A31: Masse après étuvage, prise d'essai + tare : | K31: M3=…….….. | M31: 230.8 | O31: 232.6 | P31: …...g.
A33: TENEUR EN EAU:
A35: mw: masse de l'eau évaporée lors de l'étuvage
A36: md : masse des grains solides
S37: =(M29-M31)/(M31-M27)*100 -> 11.327524 | T37: =(O29-O31)/(O31-O27)*100 -> 10.981781
A41: W= | F41: =AVERAGE(S37:T37) -> 11.154653 | I41: .…...…%
A46: Responsable de l'essai: | I46: Exécuté par
A50: BEANGE Grace | I50: MBANI Mélaine

Sheet Granulo P1
B1: PROCES-VERBAL D'ESSAIS | L1: Référence: | N1: :FEE/310/18
A2: Direction du Laboratoire | B2: Sols : reconnaissance et essais Analyse granulométrique : Méthode par tamisage à sec après lavage | L2: Indice | N2: :0 1
L3: Date appl | N3: :30-10-2018
B4: NF P 94-056/ Mars 1996 | L4: Page | N4: : 1/1
A6: Date de l'essai: | B6: 43811 | F6: Référence échantillon: | K6: Puit 2 - 2ème couche
A9: Masse minimale de la prise d'essai:
A12: dm (mm) | B12: 5 | C12: 6.3 | D12: 8 | E12: 10 | F12: 12.5 | G12: 16 | H12: 20 | I12: 25 | J12: 31.5 | K12: 40 | L12: 63 | M12: 80 | N12: dm >80mm
A13: Masse (g) | B13: 0.3 | C13: 0.4 | D13: 0.5 | E13: 0.8 | F13: 1.2 | G13: 2 | H13: 3 | I13: 5 | J13: 8 | K13: 12 | L13: 30 | M13: 50 | N13: m=6.106 dm 3,66
A15: Matériau | B15: Masse de la prisse d'essai | E15: Tamis | H15: Masse refus mesuré (g) | L15: Masse refus R cumulé (g) | N15: Pourcentage massique
A17: dm= mm | B17: m= | C17: 300 | D17: g | E17: mm | F17: µm | H17: r i | J17: R | N17: Refus cumulé r | O17: Tamisât cumulé p
A19: Partage au tamis dc : | D19: ..mm | E19: 100
E20: 80
A21: Masse sèche du refus au tamis dc: | E21: 63
A22: RC=………………… | D22: …….g | E22: 50
A23: Masse passant au tamis dc: | E23: 40 | L23: =J23 -> 0 | N23: =L23/C17*100 -> 0 | O23: =100-N23 -> 100
A24: mh= ………………. | D24: …….g | E24: 31.5 | L24: =L23+J24 -> 0 | N24: =L24/C17*100 -> 0 | O24: =100-N24 -> 100
A25: Part (1) sur tamisat au tamis dc | B25: Masse humide: | E25: 25
B26: Mh1 =.. | D26: ……..g | E26: 20 | L26: =J26+L24 -> 0 | N26: =L26/C17*100 -> 0 | O26: =100-N26 -> 100
B27: Masse sèche: | E27: 16
B28: Ms1 | D28: ..…..g | E28: 12.5
A29: Part (2) sur tamisat au tamis dc | B29: Masse humide: | E29: 10 | J29: 24.8 | L29: =J29+L26 -> 24.8 | N29: =L29/C17*100 -> 8.2666667 | O29: =100-N29 -> 91.733333
B30: Mh1 =.. | D30: ……..g | E30: 8
B31: Masse sèche: | E31: 6.3
B32: Ms1… | D32: ……..g | E32: 5 | J32: 4.2 | L32: =J32+L29 -> 29 | N32: =L32/C17*100 -> 9.6666667 | O32: =100-N32 -> 90.333333
A33: Masse sèche totale: | E33: 4
A34: ms=Rc+mh.ms1/mh1=…… | D34: ……..g | E34: 3.15
A35: Coefficient multiplicateur sur le refus au tamis de 80µm: | E35: 2.5
E36: 2 | J36: 3.7 | L36: =J36+L32 -> 32.7 | N36: =L36/C17*100 -> 10.9 | O36: =100-N36 -> 89.1
A37: b=mh/mh2:……..……….. | D37: ………. | E37: 1.6
A38: Refus cumulé R = RC + br1 | E38: 1.25
A39: Masse (80µm,dc):ms4= Prélèvement 2 | D39: ……..g | E39: 1 | J39: 5.2 | L39: =J39+L36 -> 37.9 | N39: =L39/C17*100 -> 12.633333 | O39: =100-N39 -> 87.366667
E40: 0.8 | F40: 800
A41: Masse passant à 80µm de lafraction (80µm,dc ): | E41: 0.63 | F41: 630
E42: 0.5 | F42: 500
A43: Sur part(2)ms3 =……………. | D43: ……g | E43: 0.4 | F43: 400 | J43: 47.9 | L43: =J43+L39 -> 85.8 | N43: =L43/C17*100 -> 28.6 | O43: =100-N43 -> 71.4
E44: 0.315 | F44: 315 | U44: 60.4
A45: Pourcentage | C45: Refus: | E45: 0.25 | F45: 250 | U45: 128.7
C46: R = 100 R/ms | E46: 0.2 | F46: 200 | J46: 76.7 | L46: =J46+L43 -> 162.5 | N46: =L46/C17*100 -> 54.166667 | O46: =100-N46 -> 45.833333 | U46: 81.4
C47: De tamisat: | E47: 0.16 | F47: 160 | U47: 11.9
C48: 100(1-R/ms) | E48: 0.125 | F48: 125
...

Sheet Courbe P1 (2)
B1: PROCES-VERBAL D'ESSAIS | L1: Référence: | N1: :FEE/310/18
A2: Direction du Laboratoire | B2: Sols : reconnaissance et essais Analyse granulométrique : Méthode par tamisage à sec après lavage | L2: Indice | N2: :0 1
L3: Date appl | N3: :30-10-2018
B4: Effectuée conformement à la norme NF P 94-056/ Mars 1996 | L4: Page | N4: : 1/1
A6: Date de l'essai: | B6: ='Granulo P1'!B6:E6 -> 43811 | G6: Référence échantillon: | L6: ='Granulo P1'!K6 -> Puit 2 - 2ème couche
A9: Masse minimale de la prise d'essai:
A12: dm (mm) | B12: 5 | C12: 6.3 | D12: 8 | E12: 10 | F12: 12.5 | G12: 16 | H12: 20 | I12: 25 | J12: 31.5 | K12: 40 | L12: 63 | M12: 80 | N12: dm >80mm
A13: Masse (g) | B13: 0.3 | C13: 0.4 | D13: 0.5 | E13: 0.8 | F13: 1.2 | G13: 2 | H13: 3 | I13: 5 | J13: 8 | K13: 12 | L13: 30 | M13: 50 | N13: m=6.106 dm 3,66
T19: 40 | U19: ='Granulo P1'!O23 -> 100
T20: 31.5 | U20: ='Granulo P1'!O24 -> 100
T21: 20 | U21: ='Granulo P1'!O26 -> 100
T22: 10 | U22: ='Granulo P1'!O29 -> 91.733333
T23: 5 | U23: ='Granulo P1'!O32 -> 90.333333
T24: 2 | U24: ='Granulo P1'!O36 -> 89.1
T25: 1 | U25: ='Granulo P1'!O39 -> 87.366667 | X25: 100
T26: 0.4 | U26: ='Granulo P1'!O43 -> 71.4 | X26: 81.966667
T27: 0.2 | U27: ='Granulo P1'!O46 -> 45.833333 | X27: 39.066667
T28: 0.1 | U28: ='Granulo P1'!O49 -> 24.133333 | X28: 11.933333
T29: 0.08 | U29: ='Granulo P1'!O50 -> 21.4 | X29: 7.9666667

Sheet PS
A11: POIDS SPECIFIQUE
G13: Date : 16/12/2019
E15: Expérimentateur :BEANGE Grace
A16: Nature :Passage en TVC Gré de Linkisi) ,Profondeur 0,35 m - 0,40 m,Puit 2 - 2 ème couche
A17: N° PYCNOMETRE | G17: 8 | H17: 4
A18: Poids Pycnomètre vide = PO | G18: 259.4 | H18: 289
A20: Poids Pycnomètre + Matériaux Sec = P2 | G20: 610.1 | H20: 639.9
A22: Poids Pycnomètre + Matériaux +Eau =P3 | G22: 1005.5 | H22: 1026.2
A24: Poids Pycnomètre + Eau =P1 | G24: 793.5 | H24: 814.2
A28: Volume Pycnomètre = P1-P0 = P4 | G28: =G24-G18 -> 534.1 | H28: =H24-H18 -> 525.2
A30: Volume Matériaux Net Sec = P2-P0 = P5 | G30: =G20-G18 -> 350.7 | H30: =H20-H18 -> 350.9
A32: Volume d'Eau Restant = P3-P2= P6 | G32: =G22-G20 -> 395.4 | H32: =H22-H20 -> 386.3
A34: Volume Matériaux = P4-P6= VM* | G34: =G28-G32 -> 138.7 | H34: =H28-H32 -> 138.9
A38: Poids Spécifique | G38: =G30/G34 -> 2.5284787 | H38: =H30/H34 -> 2.5262779
A42: Moyenne | G42: =AVERAGE(G38,H38,I38) -> 2.5273783
A44: Observation:
A46: Opérateur: | E46: Chargé d'affaire:

Sheet EQUIVALENTE (2)
C1: Procès verbal d'essai
C2: Essai pour déterminer les caractéristiques géométriques des granulats
C3: Partie 8 : Equivalent de sable
C4: NF EN 933 -8 /Mars 2012
B6: Référence de l'échantillon : TM 01 0,00 - 0,30 | E6: Date de l'essai: 02/10/2019
B8: 1 préparation des éprouvettes
B9: Teneur en eau des échantillons | E9: % (exprimée à 0,1 % près)
B10: Masse M1 | E10: g
B11: Masse M 2 | E11: g
B12: Masse M 3 | E12: g
B13: Teneur en fines | E13: %
A15: Remarques :
B16: •Si la fraction est 0/2 mm,la teneur en humidité doit etre inférieure à 2 % et l'essai doit etre réalisé
B17: à la température de (23 ± 3)°c.
B18: •Si la fraction est 0/4 mm,la teneur en humidité doit etre inférieur à 8 % et l'essai doit etre réalisé
B19: à la température de (23 ± 3)°c.
E22: 1 ère éprouvette | G22: 2 ème éprouvette
B23: Masse de l'éprouvette Mt g | E23: 120 g | G23: 120 g | L23: 0.0027777778
B24: H 1 (mm) | E24: 10.2 | G24: 9.9 | L24: 0.0069444444
B25: H 2 (mm) | E25: 8.3 | G25: 8.2 | L25: 0.0020833333
B26: 100 *(h 2 / h 1 ) ( enregistré à un chiffre après la virgule ) | E26: =E25/E24*100 -> 81.372549 | G26: =G25/G24*100 -> 82.828283 | L26: 0.013888889
B28: Note :Il convient que les valeurs de 100 * (h2/h1) pour les deux éprouvettes ne diffère pas
B29: de plus de 4 .
B30: Equivalent de sable (SE) est la moyenne de 100 * (h2/h1) pour les deux éprouvettes exprimée au | J30: =IF(#REF!="","",AVERAGE(E28:J28))% -> #REF!
B31: entier le plus proche .
B32: Cas d'un sable 0/2 mm | E32: Cas d'un sable 0/4 mm
B34: SE 2 = | D34: =AVERAGE(E26:H27) -> 82.100416 | F34: SE 4 =
B36: Observations :
E37: Responsable de l'essai : DEOLINDA N'TONTA
E39: Nom :
E41: Visa :
